def fancy_divide(numbers,index):
    try:
        denom = numbers[index]
        for i in range(len(numbers)):
            numbers[i] /= denom
    except IndexError:
        print("-1")
    else:
        print("1")
    finally:
        print("0")
        
fancy_divide([0, 2, 4], 0)
#okay, so is it because there isn't a Zero Division exception that the program exits out of the try block without ever hitting the finally? 